<?xml version="1.0" ?>
<!-- =================================================================================== -->
<!-- |    This document was autogenerated by xacro from /home/harivathsha/inter_iit/src/wh_bot/description/robot.urdf.xacro | -->
<!-- |    EDITING THIS FILE BY HAND IS NOT RECOMMENDED                                 | -->
<!-- =================================================================================== -->
<robot name="hv_bot">
  <material name="black">
    <color rgba="0.0 0.0 0.0 1.0"/>
  </material>
  <material name="blue">
    <color rgba="0.0 0.0 0.8 1.0"/>
  </material>
  <material name="green">
    <color rgba="0.0 0.8 0.0 1.0"/>
  </material>
  <material name="yellow">
    <color rgba="1.0 1.0 0.0 1.0"/>
  </material>
  <material name="dark_grey">
    <color rgba="0.2 0.2 0.2 1.0"/>
  </material>
  <material name="orange">
    <color rgba="1.0 0.4235294117647059 0.0392156862745098 1.0"/>
  </material>
  <material name="brown">
    <color rgba="0.5450980392156862 0.27058823529411763 0.07450980392156863 1.0"/>
  </material>
  <material name="red">
    <color rgba="0.8 0.0 0.0 1.0"/>
  </material>
  <material name="turquoise">
    <color rgba="0.25098039215686274 0.8784313725490196 0.8156862745098039 1.0"/>
  </material>
  <material name="purple">
    <color rgba="0.5019607843137255 0.0 0.5019607843137255 1.0"/>
  </material>
  <material name="white">
    <color rgba="1.0 1.0 1.0 1.0"/>
  </material>
  <material name="aluminium">
    <color rgba="0.5 0.5 0.5 1"/>
  </material>
  <material name="plastic">
    <color rgba="0.1 0.1 0.1 1"/>
  </material>
  <material name="silver">
    <color rgba="0.700 0.700 0.700 1.000"/>
  </material>
  <link name="base_footprint"/>
  <joint name="base_joint" type="fixed">
    <parent link="base_footprint"/>
    <child link="base_link"/>
    <origin rpy="0 0 0" xyz="0 0 0.0"/>
  </joint>
  <link name="base_link">
    <inertial>
      <origin rpy="0 0 0" xyz="-0.0015875113590969646 0.0010000000000003695 0.08310632933151538"/>
      <mass value="249.98671519892"/>
      <inertia ixx="3.129688" ixy="0.0" ixz="0.051946" iyy="6.917516" iyz="0.0" izz="8.85739"/>
    </inertial>
    <visual>
      <origin rpy="0 0 0" xyz="0 0 0"/>
      <geometry>
        <mesh filename="file:///home/harivathsha/inter_iit/install/wh_bot/share/wh_bot/meshes/tirth_bot/base_link.stl" scale="0.001 0.001 0.001"/>
      </geometry>
      <material name="silver"/>
    </visual>
    <collision>
      <origin rpy="0 0 0" xyz="0 0 0"/>
      <geometry>
        <mesh filename="file:///home/harivathsha/inter_iit/install/wh_bot/share/wh_bot/meshes/tirth_bot/base_link.stl" scale="0.001 0.001 0.001"/>
      </geometry>
    </collision>
  </link>
  <link name="wheel1_1">
    <inertial>
      <origin rpy="0 0 0" xyz="-7.069047372045812e-15 0.005000000000000615 4.2674197509029455e-16"/>
      <mass value="2.436309815247864"/>
      <inertia ixx="0.001866" ixy="0.0" ixz="0.0" iyy="0.003082" iyz="-0.0" izz="0.001866"/>
    </inertial>
    <visual>
      <origin rpy="0 0 0" xyz="-0.0 0.214 -0.029"/>
      <geometry>
        <mesh filename="file:///home/harivathsha/inter_iit/install/wh_bot/share/wh_bot/meshes/tirth_bot/wheel1_1.stl" scale="0.001 0.001 0.001"/>
      </geometry>
      <material name="silver"/>
    </visual>
    <collision>
      <origin rpy="0 0 0" xyz="-0.0 0.214 -0.029"/>
      <geometry>
        <mesh filename="file:///home/harivathsha/inter_iit/install/wh_bot/share/wh_bot/meshes/tirth_bot/wheel1_1.stl" scale="0.001 0.001 0.001"/>
      </geometry>
    </collision>
  </link>
  <link name="wheel2_1">
    <inertial>
      <origin rpy="0 0 0" xyz="-6.997305755651476e-15 -0.004999999999999727 -1.97758476261356e-16"/>
      <mass value="2.436309815247864"/>
      <inertia ixx="0.001866" ixy="0.0" ixz="0.0" iyy="0.003082" iyz="-0.0" izz="0.001866"/>
    </inertial>
    <visual>
      <origin rpy="0 0 0" xyz="-0.0 -0.216 -0.029"/>
      <geometry>
        <mesh filename="file:///home/harivathsha/inter_iit/install/wh_bot/share/wh_bot/meshes/tirth_bot/wheel2_1.stl" scale="0.001 0.001 0.001"/>
      </geometry>
      <material name="silver"/>
    </visual>
    <collision>
      <origin rpy="0 0 0" xyz="-0.0 -0.216 -0.029"/>
      <geometry>
        <mesh filename="file:///home/harivathsha/inter_iit/install/wh_bot/share/wh_bot/meshes/tirth_bot/wheel2_1.stl" scale="0.001 0.001 0.001"/>
      </geometry>
    </collision>
  </link>
  <link name="mount_rod_1">
    <inertial>
      <origin rpy="0 0 0" xyz="-1.2434497875801754e-16 1.9060274192295168e-15 0.8325"/>
      <mass value="6.415843965715935"/>
      <inertia ixx="1.482431" ixy="0.0" ixz="-0.0" iyy="1.482431" iyz="-0.0" izz="0.000501"/>
    </inertial>
    <visual>
      <origin rpy="0 0 0" xyz="-0.0 -0.001 -0.159"/>
      <geometry>
        <mesh filename="file:///home/harivathsha/inter_iit/install/wh_bot/share/wh_bot/meshes/tirth_bot/mount_rod_1.stl" scale="0.001 0.001 0.001"/>
      </geometry>
      <material name="silver"/>
    </visual>
    <collision>
      <origin rpy="0 0 0" xyz="-0.0 -0.001 -0.159"/>
      <geometry>
        <mesh filename="file:///home/harivathsha/inter_iit/install/wh_bot/share/wh_bot/meshes/tirth_bot/mount_rod_1.stl" scale="0.001 0.001 0.001"/>
      </geometry>
    </collision>
  </link>
  <link name="camera_mount_1">
    <inertial>
      <origin rpy="0 0 0" xyz="0.02191850421636773 -0.05786812721988108 0.044453307589603974"/>
      <mass value="1.2795442026083157"/>
      <inertia ixx="0.003671" ixy="0.000228" ixz="-0.000156" iyy="0.003582" iyz="0.000411" izz="0.003515"/>
    </inertial>
    <visual>
      <origin rpy="0 0 0" xyz="-0.0 -0.001 -0.164"/>
      <geometry>
        <mesh filename="file:///home/harivathsha/inter_iit/install/wh_bot/share/wh_bot/meshes/tirth_bot/camera_mount_1.stl" scale="0.001 0.001 0.001"/>
      </geometry>
      <material name="silver"/>
    </visual>
    <collision>
      <origin rpy="0 0 0" xyz="-0.0 -0.001 -0.164"/>
      <geometry>
        <mesh filename="file:///home/harivathsha/inter_iit/install/wh_bot/share/wh_bot/meshes/tirth_bot/camera_mount_1.stl" scale="0.001 0.001 0.001"/>
      </geometry>
    </collision>
  </link>
  <link name="castor_wheel_1_1">
    <inertial>
      <origin rpy="0 0 0" xyz="-4.972146569470759e-08 -2.436661393906414e-07 -0.007006365450839825"/>
      <mass value="0.0556888162577893"/>
      <inertia ixx="4e-06" ixy="-0.0" ixz="0.0" iyy="6e-06" iyz="-0.0" izz="8e-06"/>
    </inertial>
    <visual>
      <origin rpy="0 0 0" xyz="-0.183907 0.093505 -0.0"/>
      <geometry>
        <mesh filename="file:///home/harivathsha/inter_iit/install/wh_bot/share/wh_bot/meshes/tirth_bot/castor_wheel_1_1.stl" scale="0.001 0.001 0.001"/>
      </geometry>
      <material name="silver"/>
    </visual>
    <collision>
      <origin rpy="0 0 0" xyz="-0.183907 0.093505 -0.0"/>
      <geometry>
        <mesh filename="file:///home/harivathsha/inter_iit/install/wh_bot/share/wh_bot/meshes/tirth_bot/castor_wheel_1_1.stl" scale="0.001 0.001 0.001"/>
      </geometry>
    </collision>
  </link>
  <link name="castor_wheel_2_1">
    <inertial>
      <origin rpy="0 0 0" xyz="4.969382808028833e-08 -2.4366613946003035e-07 -0.007006365450839813"/>
      <mass value="0.05568881625778935"/>
      <inertia ixx="4e-06" ixy="-0.0" ixz="0.0" iyy="6e-06" iyz="-0.0" izz="8e-06"/>
    </inertial>
    <visual>
      <origin rpy="0 0 0" xyz="0.183907 0.093505 -0.0"/>
      <geometry>
        <mesh filename="file:///home/harivathsha/inter_iit/install/wh_bot/share/wh_bot/meshes/tirth_bot/castor_wheel_2_1.stl" scale="0.001 0.001 0.001"/>
      </geometry>
      <material name="silver"/>
    </visual>
    <collision>
      <origin rpy="0 0 0" xyz="0.183907 0.093505 -0.0"/>
      <geometry>
        <mesh filename="file:///home/harivathsha/inter_iit/install/wh_bot/share/wh_bot/meshes/tirth_bot/castor_wheel_2_1.stl" scale="0.001 0.001 0.001"/>
      </geometry>
    </collision>
  </link>
  <link name="castor_wheel_3_1">
    <inertial>
      <origin rpy="0 0 0" xyz="-4.9702650495309086e-08 2.43661259252681e-07 -0.00700636551245724"/>
      <mass value="0.05568881625778933"/>
      <inertia ixx="4e-06" ixy="-0.0" ixz="0.0" iyy="6e-06" iyz="-0.0" izz="8e-06"/>
    </inertial>
    <visual>
      <origin rpy="0 0 0" xyz="-0.183907 -0.095505 0.0"/>
      <geometry>
        <mesh filename="file:///home/harivathsha/inter_iit/install/wh_bot/share/wh_bot/meshes/tirth_bot/castor_wheel_3_1.stl" scale="0.001 0.001 0.001"/>
      </geometry>
      <material name="silver"/>
    </visual>
    <collision>
      <origin rpy="0 0 0" xyz="-0.183907 -0.095505 0.0"/>
      <geometry>
        <mesh filename="file:///home/harivathsha/inter_iit/install/wh_bot/share/wh_bot/meshes/tirth_bot/castor_wheel_3_1.stl" scale="0.001 0.001 0.001"/>
      </geometry>
    </collision>
  </link>
  <link name="castor_wheel_4_1">
    <inertial>
      <origin rpy="0 0 0" xyz="4.971086078886522e-08 2.436665172828034e-07 -0.007006365449132579"/>
      <mass value="0.05568881625166658"/>
      <inertia ixx="4e-06" ixy="-0.0" ixz="-0.0" iyy="6e-06" iyz="-0.0" izz="8e-06"/>
    </inertial>
    <visual>
      <origin rpy="0 0 0" xyz="0.183907 -0.095505 0.0"/>
      <geometry>
        <mesh filename="file:///home/harivathsha/inter_iit/install/wh_bot/share/wh_bot/meshes/tirth_bot/castor_wheel_4_1.stl" scale="0.001 0.001 0.001"/>
      </geometry>
      <material name="silver"/>
    </visual>
    <collision>
      <origin rpy="0 0 0" xyz="0.183907 -0.095505 0.0"/>
      <geometry>
        <mesh filename="file:///home/harivathsha/inter_iit/install/wh_bot/share/wh_bot/meshes/tirth_bot/castor_wheel_4_1.stl" scale="0.001 0.001 0.001"/>
      </geometry>
    </collision>
  </link>
  <joint name="revolute_1" type="continuous">
    <origin rpy="0 0 0" xyz="0.0 -0.214 0.029"/>
    <parent link="base_link"/>
    <child link="wheel1_1"/>
    <axis xyz="-0.0 -1.0 0.0"/>
  </joint>
  <joint name="revolute_2" type="continuous">
    <origin rpy="0 0 0" xyz="0.0 0.216 0.029"/>
    <parent link="base_link"/>
    <child link="wheel2_1"/>
    <axis xyz="0.0 1.0 -0.0"/>
  </joint>
  <joint name="rigid_1" type="fixed">
    <origin rpy="0 0 0" xyz="0.0 0.001 0.159"/>
    <parent link="base_link"/>
    <child link="mount_rod_1"/>
  </joint>
  <joint name="joint_lift_2" type="prismatic">
    <origin rpy="0 0 0" xyz="0.0 0.001 0.164"/>
    <parent link="base_link"/>
    <child link="camera_mount_1"/>
    <axis xyz="0.0 0.0 1.0"/>
    <limit effort="100" lower="0.0" upper="1.8" velocity="100"/>
  </joint>
  <joint name="rigid_2" type="fixed">
    <origin rpy="0 0 0" xyz="0.183907 -0.093505 0.0"/>
    <parent link="base_link"/>
    <child link="castor_wheel_1_1"/>
  </joint>
  <joint name="rigid_3" type="fixed">
    <origin rpy="0 0 0" xyz="-0.183907 -0.093505 0.0"/>
    <parent link="base_link"/>
    <child link="castor_wheel_2_1"/>
  </joint>
  <joint name="rigid_4" type="fixed">
    <origin rpy="0 0 0" xyz="0.183907 0.095505 0.0"/>
    <parent link="base_link"/>
    <child link="castor_wheel_3_1"/>
  </joint>
  <joint name="rigid_5" type="fixed">
    <origin rpy="0 0 0" xyz="-0.183907 0.095505 0.0"/>
    <parent link="base_link"/>
    <child link="castor_wheel_4_1"/>
  </joint>
  <!-- ........................... SENSOR PLUGIN ................................... -->
  <gazebo>
    <plugin filename="gz-sim-sensors-system" name="gz::sim::systems::Sensors">
      <render_engine>ogre2</render_engine>
    </plugin>
    <plugin filename="gz-sim-imu-system" name="gz::sim::systems::Imu">
        </plugin>
    <plugin filename="gz-sim-diff-drive-system" name="gz::sim::systems::DiffDrive">
      <left_joint>revolute_1</left_joint>
      <right_joint>revolute_2</right_joint>
      <wheel_separation>0.46</wheel_separation>
      <wheel_radius>0.05</wheel_radius>
      <odom_publish_frequency>30</odom_publish_frequency>
      <topic>/cmd_vel</topic>
      <odom_topic>odom</odom_topic>
      <tf_topic>/tf</tf_topic>
      <frame_id>odom</frame_id>
      <child_frame_id>base_footprint</child_frame_id>
    </plugin>
    <plugin filename="gz-sim-joint-state-publisher-system" name="gz::sim::systems::JointStatePublisher">
      <topic>joint_states</topic>
      <joint_name>revolute_1</joint_name>
      <joint_name>revolute_2</joint_name>
    </plugin>
  </gazebo>
  <gazebo reference="imu_link">
    <sensor name="imu" type="imu">
      <always_on>1</always_on>
      <update_rate>50</update_rate>
      <visualize>true</visualize>
      <topic>imu</topic>
      <enable_metrics>true</enable_metrics>
      <gz_frame_id>imu_link</gz_frame_id>
    </sensor>
  </gazebo>
  <ros2_control name="GazeboSystem" type="system">
    <hardware>
      <plugin>gz_ros2_control/GazeboSimSystem</plugin>
    </hardware>
    <joint name="joint_lift_2">
      <command_interface name="position">
        <param name="min">-2</param>
        <param name="max">2</param>
      </command_interface>
      <state_interface name="position">
        <param name="initial_value">0.0</param>
      </state_interface>
      <state_interface name="velocity"/>
      <state_interface name="effort"/>
    </joint>
  </ros2_control>
  <gazebo>
    <plugin filename="libgz_ros2_control-system.so" name="gz_ros2_control::GazeboSimROS2ControlPlugin">
      <parameters>/home/harivathsha/inter_iit/install/wh_bot/share/wh_bot/config/my_controllers.yaml</parameters>
      <parameters>/home/harivathsha/inter_iit/install/wh_bot/share/wh_bot/config/gaz_ros2_ctl_use_sim.yaml</parameters>
    </plugin>
  </gazebo>
  <!-- STEREO CAMERA -->
  <link name="stereo_camera">
    <collision>
      <origin rpy="0 0 0" xyz="0 0 0"/>
      <geometry>
        <box size="0.07 0.3 0.09"/>
      </geometry>
    </collision>
    <visual>
      <origin rpy="0 0 0" xyz="0 0 0"/>
      <geometry>
        <mesh filename="file:///home/harivathsha/inter_iit/install/wh_bot/share/wh_bot/meshes/kinect/d415.dae"/>
      </geometry>
      <material name="black"/>
    </visual>
    <inertial>
      <mass value="0.01"/>
      <inertia ixx="3.129688" ixy="0.051946" ixz="0.0" iyy="8.85739" iyz="0.0" izz="6.917516"/>
    </inertial>
  </link>
  <joint name="stereo_camera_joint" type="fixed">
    <origin rpy="0 0 1.57" xyz="0.00819398999214172 0.0205205416083335876 0.02934401321411133"/>
    <parent link="camera_mount_1"/>
    <child link="stereo_camera"/>
  </joint>
  <link name="stereo_camera_optical"/>
  <joint name="stereo_camera_optical_joint" type="fixed">
    <origin rpy="-1.5707963267948966 0 -1.5707963267948966" xyz="0 0 0"/>
    <parent link="stereo_camera"/>
    <child link="stereo_camera_optical"/>
  </joint>
  <gazebo reference="stereo_camera">
    <sensor name="right" type="camera">
      <update_rate>10.0</update_rate>
      <always_on>true</always_on>
      <gz_frame_id>stereo_camera_optical</gz_frame_id>
      <pose>0 -0.12 0 0 0 0</pose>
      <topic>z_axis_camera_2/image_raw</topic>
      <camera_info_topic>z_axis_camera_2/camera_info</camera_info_topic>
      <horizontal_fov>1.3962634</horizontal_fov>
      <image>
        <width>1980</width>
        <height>1020</height>
        <format>R8G8B8</format>
      </image>
      <clip>
        <near>0.01</near>
        <far>20</far>
      </clip>
    </sensor>
  </gazebo>
  <link name="kinect_camera">
    <collision>
      <origin rpy="0 0 0" xyz="0 0 0"/>
      <geometry>
        <box size="0.07 0.3 0.09"/>
      </geometry>
    </collision>
    <visual>
      <origin rpy="0 0 0" xyz="0 0 0"/>
      <geometry>
        <mesh filename="file:///home/harivathsha/inter_iit/install/wh_bot/share/wh_bot/meshes/kinect/d415.dae"/>
      </geometry>
      <material name="black"/>
    </visual>
    <inertial>
      <mass value="0.01"/>
      <inertia ixx="3.129688" ixy="0.051946" ixz="0.0" iyy="8.85739" iyz="0.0" izz="6.917516"/>
    </inertial>
  </link>
  <joint name="kinect_camera_joint" type="fixed">
    <origin rpy="1.57 0 -3.14" xyz="-0.0044510997831821442 0.17352999746799469 4.175328238010406494"/>
    <parent link="body_1"/>
    <child link="kinect_camera"/>
  </joint>
  <link name="kinect_camera_optical"/>
  <joint name="kinect_camera_optical_joint" type="fixed">
    <origin rpy="-1.5707963267948966 0 -1.5707963267948966" xyz="0 0 0"/>
    <parent link="kinect_camera"/>
    <child link="kinect_camera_optical"/>
  </joint>
  <gazebo reference="kinect_camera">
    <sensor name="kinect_camera" type="depth_camera">
      <update_rate>30.0</update_rate>
      <topic>kinect_camera</topic>
      <gz_frame_id>kinect_camera</gz_frame_id>
      <camera>
        <camera_info_topic>kinect_camera/camera_info</camera_info_topic>
        <horizontal_fov>1.343222</horizontal_fov>
        <image>
          <width>640</width>
          <height>480</height>
          <format>R8G8B8</format>
        </image>
        <clip>
          <near>0.15</near>
          <far>6.0</far>
        </clip>
      </camera>
    </sensor>
    <sensor name="rgb_camera" type="camera">
      <update_rate>30.0</update_rate>
      <topic>rgb_camera</topic>
      <gz_frame_id>kinect_camera</gz_frame_id>
      <camera>
        <camera_info_topic>rgb_camera/camera_info</camera_info_topic>
        <horizontal_fov>1.34322</horizontal_fov>
        <image>
          <width>640</width>
          <height>480</height>
          <format>R8G8B8</format>
        </image>
        <clip>
          <near>0.15</near>
          <far>6.0</far>
        </clip>
      </camera>
    </sensor>
  </gazebo>
</robot>
