<?xml version="1.0" ?>
<!-- =================================================================================== -->
<!-- |    This document was autogenerated by xacro from /home/harivathsha/articubot_one-new_gazebo/src/articubot_one/description/robot.urdf.xacro | -->
<!-- |    EDITING THIS FILE BY HAND IS NOT RECOMMENDED                                 | -->
<!-- =================================================================================== -->
<robot name="robot">
  <material name="black">
    <color rgba="0.0 0.0 0.0 1.0"/>
  </material>
  <material name="blue">
    <color rgba="0.0 0.0 0.8 1.0"/>
  </material>
  <material name="green">
    <color rgba="0.0 0.8 0.0 1.0"/>
  </material>
  <material name="yellow">
    <color rgba="1.0 1.0 0.0 1.0"/>
  </material>
  <material name="dark_grey">
    <color rgba="0.2 0.2 0.2 1.0"/>
  </material>
  <material name="orange">
    <color rgba="1.0 0.4235294117647059 0.0392156862745098 1.0"/>
  </material>
  <material name="brown">
    <color rgba="0.5450980392156862 0.27058823529411763 0.07450980392156863 1.0"/>
  </material>
  <material name="red">
    <color rgba="0.8 0.0 0.0 1.0"/>
  </material>
  <material name="turquoise">
    <color rgba="0.25098039215686274 0.8784313725490196 0.8156862745098039 1.0"/>
  </material>
  <material name="purple">
    <color rgba="0.5019607843137255 0.0 0.5019607843137255 1.0"/>
  </material>
  <material name="white">
    <color rgba="1.0 1.0 1.0 1.0"/>
  </material>
  <material name="aluminium">
    <color rgba="0.5 0.5 0.5 1"/>
  </material>
  <material name="plastic">
    <color rgba="0.1 0.1 0.1 1"/>
  </material>
  <material name="silver">
    <color rgba="0.700 0.700 0.700 1.000"/>
  </material>
  <!-- Specify some standard inertial calculations https://en.wikipedia.org/wiki/List_of_moments_of_inertia -->
  <!-- These make use of xacro's mathematical functionality -->
  <link name="base_link">
    <inertial>
      <origin rpy="0 0 0" xyz="-0.0015875 0.001 0.0831"/>
      <mass value="15.0"/>
      <inertia ixx="0.3" ixy="0.0" ixz="0.0" iyy="0.6" iyz="0.0" izz="0.8"/>
    </inertial>
    <visual>
      <origin rpy="0 0 0" xyz="0 0 0"/>
      <geometry>
        <mesh filename="file:///home/harivathsha/articubot_one-new_gazebo/install/wh_bot/share/wh_bot/meshes/tirth_bot/base_link.stl" scale="0.001 0.001 0.001"/>
      </geometry>
      <material name="silver"/>
    </visual>
    <collision>
      <origin rpy="0 0 0" xyz="0 0 0"/>
      <geometry>
        <mesh filename="file:///home/harivathsha/articubot_one-new_gazebo/install/wh_bot/share/wh_bot/meshes/tirth_bot/base_link.stl" scale="0.001 0.001 0.001"/>
      </geometry>
    </collision>
  </link>
  <link name="wheel1_1">
    <inertial>
      <origin rpy="0 0 0" xyz="0 0 0"/>
      <mass value="2.436"/>
      <inertia ixx="0.0018" ixy="0.0" ixz="0.0" iyy="0.003" iyz="0.0" izz="0.0018"/>
    </inertial>
    <visual>
      <origin rpy="0 0 0" xyz="-0.0 0.214 -0.029"/>
      <geometry>
        <mesh filename="file:///home/harivathsha/articubot_one-new_gazebo/install/wh_bot/share/wh_bot/meshes/tirth_bot/wheel1_1.stl" scale="0.001 0.001 0.001"/>
      </geometry>
      <material name="silver"/>
    </visual>
    <collision>
      <origin rpy="-1.5707 0 0" xyz="0 0 0"/>
      <geometry>
        <cylinder length="0.02" radius="0.05"/>
      </geometry>
    </collision>
  </link>
  <link name="wheel2_1">
    <inertial>
      <origin rpy="0 0 0" xyz="0 0 0"/>
      <mass value="2.436"/>
      <inertia ixx="0.0018" ixy="0.0" ixz="0.0" iyy="0.003" iyz="0.0" izz="0.0018"/>
    </inertial>
    <visual>
      <origin rpy="0 0 0" xyz="-0.0 -0.216 -0.029"/>
      <geometry>
        <mesh filename="file:///home/harivathsha/articubot_one-new_gazebo/install/wh_bot/share/wh_bot/meshes/tirth_bot/wheel2_1.stl" scale="0.001 0.001 0.001"/>
      </geometry>
      <material name="silver"/>
    </visual>
    <collision>
      <origin rpy="-1.5707 0 0" xyz="0 0 0"/>
      <geometry>
        <cylinder length="0.02" radius="0.05"/>
      </geometry>
    </collision>
  </link>
  <link name="mount_rod_1">
    <inertial>
      <origin rpy="0 0 0" xyz="0 0 0.8325"/>
      <mass value="6.415"/>
      <inertia ixx="1.482" ixy="0.0" ixz="0.0" iyy="1.482" iyz="0.0" izz="0.0005"/>
    </inertial>
    <visual>
      <origin rpy="0 0 0" xyz="-0.0 -0.001 -0.159"/>
      <geometry>
        <mesh filename="file:///home/harivathsha/articubot_one-new_gazebo/install/wh_bot/share/wh_bot/meshes/tirth_bot/mount_rod_1.stl" scale="0.001 0.001 0.001"/>
      </geometry>
      <material name="silver"/>
    </visual>
    <collision>
      <origin rpy="0 0 0" xyz="-0.0 -0.001 -0.159"/>
      <geometry>
        <mesh filename="file:///home/harivathsha/articubot_one-new_gazebo/install/wh_bot/share/wh_bot/meshes/tirth_bot/mount_rod_1.stl" scale="0.001 0.001 0.001"/>
      </geometry>
    </collision>
  </link>
  <link name="camera_mount_1">
    <inertial>
      <origin rpy="0 0 0" xyz="0.021 -0.057 0.044"/>
      <mass value="1.279"/>
      <inertia ixx="0.0036" ixy="0.0002" ixz="-0.0001" iyy="0.0035" iyz="0.0004" izz="0.0035"/>
    </inertial>
    <visual>
      <origin rpy="0 0 0" xyz="-0.0 -0.001 -0.164"/>
      <geometry>
        <mesh filename="file:///home/harivathsha/articubot_one-new_gazebo/install/wh_bot/share/wh_bot/meshes/tirth_bot/camera_mount_1.stl" scale="0.001 0.001 0.001"/>
      </geometry>
      <material name="silver"/>
    </visual>
    <collision>
      <origin rpy="0 0 0" xyz="-0.0 -0.001 -0.164"/>
      <geometry>
        <mesh filename="file:///home/harivathsha/articubot_one-new_gazebo/install/wh_bot/share/wh_bot/meshes/tirth_bot/camera_mount_1.stl" scale="0.001 0.001 0.001"/>
      </geometry>
    </collision>
  </link>
  <link name="castor_wheel_1_1">
    <inertial>
      <origin rpy="0 0 0" xyz="0 0 0"/>
      <mass value="0.055"/>
      <inertia ixx="4e-06" ixy="0.0" ixz="0.0" iyy="6e-06" iyz="0.0" izz="8e-06"/>
    </inertial>
    <visual>
      <origin rpy="0 0 0" xyz="-0.1839 0.0935 0.0"/>
      <geometry>
        <mesh filename="file:///home/harivathsha/articubot_one-new_gazebo/install/wh_bot/share/wh_bot/meshes/tirth_bot/castor_wheel_1_1.stl" scale="0.001 0.001 0.001"/>
      </geometry>
      <material name="silver"/>
    </visual>
    <collision>
      <origin rpy="0 0 0" xyz="0 0 0"/>
      <geometry>
        <sphere radius="0.018"/>
      </geometry>
    </collision>
  </link>
  <link name="castor_wheel_2_1">
    <inertial>
      <origin rpy="0 0 0" xyz="0 0 0"/>
      <mass value="0.055"/>
      <inertia ixx="4e-06" ixy="0.0" ixz="0.0" iyy="6e-06" iyz="0.0" izz="8e-06"/>
    </inertial>
    <visual>
      <origin rpy="0 0 0" xyz="0.1839 0.0935 0.0"/>
      <geometry>
        <mesh filename="file:///home/harivathsha/articubot_one-new_gazebo/install/wh_bot/share/wh_bot/meshes/tirth_bot/castor_wheel_2_1.stl" scale="0.001 0.001 0.001"/>
      </geometry>
      <material name="silver"/>
    </visual>
    <collision>
      <origin rpy="0 0 0" xyz="0 0 0"/>
      <geometry>
        <sphere radius="0.018"/>
      </geometry>
    </collision>
  </link>
  <link name="castor_wheel_3_1">
    <inertial>
      <origin rpy="0 0 0" xyz="0 0 0"/>
      <mass value="0.055"/>
      <inertia ixx="4e-06" ixy="0.0" ixz="0.0" iyy="6e-06" iyz="0.0" izz="8e-06"/>
    </inertial>
    <visual>
      <origin rpy="0 0 0" xyz="-0.1839 -0.0955 0.0"/>
      <geometry>
        <mesh filename="file:///home/harivathsha/articubot_one-new_gazebo/install/wh_bot/share/wh_bot/meshes/tirth_bot/castor_wheel_3_1.stl" scale="0.001 0.001 0.001"/>
      </geometry>
      <material name="silver"/>
    </visual>
    <collision>
      <origin rpy="0 0 0" xyz="0 0 0"/>
      <geometry>
        <sphere radius="0.018"/>
      </geometry>
    </collision>
  </link>
  <link name="castor_wheel_4_1">
    <inertial>
      <origin rpy="0 0 0" xyz="0 0 0"/>
      <mass value="0.055"/>
      <inertia ixx="4e-06" ixy="0.0" ixz="0.0" iyy="6e-06" iyz="0.0" izz="8e-06"/>
    </inertial>
    <visual>
      <origin rpy="0 0 0" xyz="0.1839 -0.0955 0.0"/>
      <geometry>
        <mesh filename="file:///home/harivathsha/articubot_one-new_gazebo/install/wh_bot/share/wh_bot/meshes/tirth_bot/castor_wheel_4_1.stl" scale="0.001 0.001 0.001"/>
      </geometry>
      <material name="silver"/>
    </visual>
    <collision>
      <origin rpy="0 0 0" xyz="0 0 0"/>
      <geometry>
        <sphere radius="0.018"/>
      </geometry>
    </collision>
  </link>
  <joint name="right_wheel_joint" type="continuous">
    <origin rpy="0 0 0" xyz="0.0 -0.214 0.029"/>
    <parent link="base_link"/>
    <child link="wheel1_1"/>
    <axis xyz="0.0 1.0 0.0"/>
  </joint>
  <joint name="left_wheel_joint" type="continuous">
    <origin rpy="0 0 0" xyz="0.0 0.216 0.029"/>
    <parent link="base_link"/>
    <child link="wheel2_1"/>
    <axis xyz="0.0 1.0 0.0"/>
  </joint>
  <joint name="rigid_1" type="fixed">
    <origin rpy="0 0 0" xyz="0.0 0.001 0.159"/>
    <parent link="base_link"/>
    <child link="mount_rod_1"/>
  </joint>
  <joint name="joint_lift_2" type="prismatic">
    <origin rpy="0 0 0" xyz="0.0 0.001 0.164"/>
    <parent link="base_link"/>
    <child link="camera_mount_1"/>
    <axis xyz="0.0 0.0 1.0"/>
    <limit effort="100" lower="-0.001" upper="1.8" velocity="100"/>
  </joint>
  <joint name="rigid_2" type="fixed">
    <origin rpy="0 0 0" xyz="0.1839 -0.0935 -0.003"/>
    <parent link="base_link"/>
    <child link="castor_wheel_1_1"/>
  </joint>
  <joint name="rigid_3" type="fixed">
    <origin rpy="0 0 0" xyz="-0.1839 -0.0935 -0.003"/>
    <parent link="base_link"/>
    <child link="castor_wheel_2_1"/>
  </joint>
  <joint name="rigid_4" type="fixed">
    <origin rpy="0 0 0" xyz="0.1839 0.0955 -0.003"/>
    <parent link="base_link"/>
    <child link="castor_wheel_3_1"/>
  </joint>
  <joint name="rigid_5" type="fixed">
    <origin rpy="0 0 0" xyz="-0.1839 0.0955 -0.003"/>
    <parent link="base_link"/>
    <child link="castor_wheel_4_1"/>
  </joint>
  <gazebo reference="wheel1_1">
    <mu1>200.0</mu1>
    <mu2>200.0</mu2>
    <kp>1000000.0</kp>
    <kd>1.0</kd>
  </gazebo>
  <gazebo reference="wheel2_1">
    <mu1>200.0</mu1>
    <mu2>200.0</mu2>
    <kp>1000000.0</kp>
    <kd>1.0</kd>
  </gazebo>
  <gazebo reference="castor_wheel_1_1">
    <mu1>0.001</mu1>
    <mu2>0.001</mu2>
  </gazebo>
  <gazebo reference="castor_wheel_2_1">
    <mu1>0.001</mu1>
    <mu2>0.001</mu2>
  </gazebo>
  <gazebo reference="castor_wheel_3_1">
    <mu1>0.001</mu1>
    <mu2>0.001</mu2>
  </gazebo>
  <gazebo reference="castor_wheel_4_1">
    <mu1>0.001</mu1>
    <mu2>0.001</mu2>
  </gazebo>
  <ros2_control name="RealRobot" type="system">
    <hardware>
      <plugin>diffdrive_arduino/DiffDriveArduinoHardware</plugin>
      <param name="left_wheel_name">left_wheel_joint</param>
      <param name="right_wheel_name">right_wheel_joint</param>
      <param name="loop_rate">30</param>
      <param name="device">/dev/ttyUSB0</param>
      <param name="baud_rate">57600</param>
      <param name="timeout_ms">1000</param>
      <param name="enc_counts_per_rev">500</param>
    </hardware>
    <joint name="left_wheel_joint">
      <command_interface name="velocity">
        <param name="min">-10</param>
        <param name="max">10</param>
      </command_interface>
      <state_interface name="position"/>
      <state_interface name="velocity"/>
    </joint>
    <joint name="right_wheel_joint">
      <command_interface name="velocity">
        <param name="min">-10</param>
        <param name="max">10</param>
      </command_interface>
      <state_interface name="position"/>
      <state_interface name="velocity"/>
    </joint>
  </ros2_control>
  <gazebo>
    <plugin filename="libgazebo_ros2_control.so" name="gazebo_ros2_control">
      <parameters>/home/harivathsha/articubot_one-new_gazebo/install/articubot_one/share/articubot_one/config/my_controllers.yaml</parameters>
      <parameters>/home/harivathsha/articubot_one-new_gazebo/install/articubot_one/share/articubot_one/config/gaz_ros2_ctl_use_sim.yaml</parameters>
    </plugin>
  </gazebo>
  <!-- <xacro:include filename="lidar.xacro" /> -->
  <!-- <xacro:include filename="camera.xacro" /> -->
  <!-- <xacro:include filename="depth_camera.xacro" /> -->
  <!-- <xacro:include filename="face.xacro" /> -->
</robot>
